Traceback (most recent call last):
  File "/usr/local/lib/python3.6/dist-packages/urllib3/connectionpool.py", line 384, in _make_request
    six.raise_from(e, None)
  File "<string>", line 2, in raise_from
  File "/usr/local/lib/python3.6/dist-packages/urllib3/connectionpool.py", line 380, in _make_request
    httplib_response = conn.getresponse()
  File "/usr/lib/python3.6/http/client.py", line 1331, in getresponse
    response.begin()
  File "/usr/lib/python3.6/http/client.py", line 297, in begin
    version, status, reason = self._read_status()
  File "/usr/lib/python3.6/http/client.py", line 258, in _read_status
    line = str(self.fp.readline(_MAXLINE + 1), "iso-8859-1")
  File "/usr/lib/python3.6/socket.py", line 586, in readinto
    return self._sock.recv_into(b)
  File "/usr/local/lib/python3.6/dist-packages/urllib3/contrib/pyopenssl.py", line 307, in recv_into
    raise timeout('The read operation timed out')
socket.timeout: The read operation timed out

During handling of the above exception, another exception occurred:

Traceback (most recent call last):
  File "/usr/local/lib/python3.6/dist-packages/requests/adapters.py", line 449, in send
    timeout=timeout
  File "/usr/local/lib/python3.6/dist-packages/urllib3/connectionpool.py", line 638, in urlopen
    _stacktrace=sys.exc_info()[2])
  File "/usr/local/lib/python3.6/dist-packages/urllib3/util/retry.py", line 367, in increment
    raise six.reraise(type(error), error, _stacktrace)
  File "/usr/local/lib/python3.6/dist-packages/urllib3/packages/six.py", line 686, in reraise
    raise value
  File "/usr/local/lib/python3.6/dist-packages/urllib3/connectionpool.py", line 600, in urlopen
    chunked=chunked)
  File "/usr/local/lib/python3.6/dist-packages/urllib3/connectionpool.py", line 386, in _make_request
    self._raise_timeout(err=e, url=url, timeout_value=read_timeout)
  File "/usr/local/lib/python3.6/dist-packages/urllib3/connectionpool.py", line 306, in _raise_timeout
    raise ReadTimeoutError(self, url, "Read timed out. (read timeout=%s)" % timeout_value)
urllib3.exceptions.ReadTimeoutError: HTTPSConnectionPool(host='www.abuseipdb.com', port=443): Read timed out. (read timeout=15.0)

During handling of the above exception, another exception occurred:

Traceback (most recent call last):
  File "/var/misc-internet-applications/Multipurpose-Regex-Webscraper/py-cmd/regexscraper.py", line 55, in raw_scrape_pages
    page_text = requests.get(site, timeout=15.00).text
  File "/usr/local/lib/python3.6/dist-packages/requests/api.py", line 75, in get
    return request('get', url, params=params, **kwargs)
  File "/usr/local/lib/python3.6/dist-packages/requests/api.py", line 60, in request
    return session.request(method=method, url=url, **kwargs)
  File "/usr/local/lib/python3.6/dist-packages/requests/sessions.py", line 533, in request
    resp = self.send(prep, **send_kwargs)
  File "/usr/local/lib/python3.6/dist-packages/requests/sessions.py", line 646, in send
    r = adapter.send(request, **kwargs)
  File "/usr/local/lib/python3.6/dist-packages/requests/adapters.py", line 529, in send
    raise ReadTimeout(e, request=request)
requests.exceptions.ReadTimeout: HTTPSConnectionPool(host='www.abuseipdb.com', port=443): Read timed out. (read timeout=15.0)


Traceback (most recent call last):
  File "/usr/local/lib/python3.6/dist-packages/urllib3/connectionpool.py", line 384, in _make_request
    six.raise_from(e, None)
  File "<string>", line 2, in raise_from
  File "/usr/local/lib/python3.6/dist-packages/urllib3/connectionpool.py", line 380, in _make_request
    httplib_response = conn.getresponse()
  File "/usr/lib/python3.6/http/client.py", line 1346, in getresponse
    response.begin()
  File "/usr/lib/python3.6/http/client.py", line 307, in begin
    version, status, reason = self._read_status()
  File "/usr/lib/python3.6/http/client.py", line 268, in _read_status
    line = str(self.fp.readline(_MAXLINE + 1), "iso-8859-1")
  File "/usr/lib/python3.6/socket.py", line 586, in readinto
    return self._sock.recv_into(b)
  File "/usr/local/lib/python3.6/dist-packages/urllib3/contrib/pyopenssl.py", line 307, in recv_into
    raise timeout('The read operation timed out')
socket.timeout: The read operation timed out

During handling of the above exception, another exception occurred:

Traceback (most recent call last):
  File "/usr/local/lib/python3.6/dist-packages/requests/adapters.py", line 449, in send
    timeout=timeout
  File "/usr/local/lib/python3.6/dist-packages/urllib3/connectionpool.py", line 638, in urlopen
    _stacktrace=sys.exc_info()[2])
  File "/usr/local/lib/python3.6/dist-packages/urllib3/util/retry.py", line 367, in increment
    raise six.reraise(type(error), error, _stacktrace)
  File "/usr/local/lib/python3.6/dist-packages/urllib3/packages/six.py", line 686, in reraise
    raise value
  File "/usr/local/lib/python3.6/dist-packages/urllib3/connectionpool.py", line 600, in urlopen
    chunked=chunked)
  File "/usr/local/lib/python3.6/dist-packages/urllib3/connectionpool.py", line 386, in _make_request
    self._raise_timeout(err=e, url=url, timeout_value=read_timeout)
  File "/usr/local/lib/python3.6/dist-packages/urllib3/connectionpool.py", line 306, in _raise_timeout
    raise ReadTimeoutError(self, url, "Read timed out. (read timeout=%s)" % timeout_value)
urllib3.exceptions.ReadTimeoutError: HTTPSConnectionPool(host='www.abuseipdb.com', port=443): Read timed out. (read timeout=15.0)

During handling of the above exception, another exception occurred:

Traceback (most recent call last):
  File "/var/misc-internet-applications/Multipurpose-Regex-Webscraper/py-cmd/regexscraper.py", line 55, in raw_scrape_pages
    page_text = requests.get(site, timeout=15.00).text
  File "/usr/local/lib/python3.6/dist-packages/requests/api.py", line 75, in get
    return request('get', url, params=params, **kwargs)
  File "/usr/local/lib/python3.6/dist-packages/requests/api.py", line 60, in request
    return session.request(method=method, url=url, **kwargs)
  File "/usr/local/lib/python3.6/dist-packages/requests/sessions.py", line 533, in request
    resp = self.send(prep, **send_kwargs)
  File "/usr/local/lib/python3.6/dist-packages/requests/sessions.py", line 646, in send
    r = adapter.send(request, **kwargs)
  File "/usr/local/lib/python3.6/dist-packages/requests/adapters.py", line 529, in send
    raise ReadTimeout(e, request=request)
requests.exceptions.ReadTimeout: HTTPSConnectionPool(host='www.abuseipdb.com', port=443): Read timed out. (read timeout=15.0)


Traceback (most recent call last):
  File "/usr/local/lib/python3.6/dist-packages/urllib3/connectionpool.py", line 384, in _make_request
    six.raise_from(e, None)
  File "<string>", line 2, in raise_from
  File "/usr/local/lib/python3.6/dist-packages/urllib3/connectionpool.py", line 380, in _make_request
    httplib_response = conn.getresponse()
  File "/usr/lib/python3.6/http/client.py", line 1346, in getresponse
    response.begin()
  File "/usr/lib/python3.6/http/client.py", line 307, in begin
    version, status, reason = self._read_status()
  File "/usr/lib/python3.6/http/client.py", line 268, in _read_status
    line = str(self.fp.readline(_MAXLINE + 1), "iso-8859-1")
  File "/usr/lib/python3.6/socket.py", line 586, in readinto
    return self._sock.recv_into(b)
  File "/usr/local/lib/python3.6/dist-packages/urllib3/contrib/pyopenssl.py", line 307, in recv_into
    raise timeout('The read operation timed out')
socket.timeout: The read operation timed out

During handling of the above exception, another exception occurred:

Traceback (most recent call last):
  File "/usr/local/lib/python3.6/dist-packages/requests/adapters.py", line 449, in send
    timeout=timeout
  File "/usr/local/lib/python3.6/dist-packages/urllib3/connectionpool.py", line 638, in urlopen
    _stacktrace=sys.exc_info()[2])
  File "/usr/local/lib/python3.6/dist-packages/urllib3/util/retry.py", line 367, in increment
    raise six.reraise(type(error), error, _stacktrace)
  File "/usr/local/lib/python3.6/dist-packages/urllib3/packages/six.py", line 686, in reraise
    raise value
  File "/usr/local/lib/python3.6/dist-packages/urllib3/connectionpool.py", line 600, in urlopen
    chunked=chunked)
  File "/usr/local/lib/python3.6/dist-packages/urllib3/connectionpool.py", line 386, in _make_request
    self._raise_timeout(err=e, url=url, timeout_value=read_timeout)
  File "/usr/local/lib/python3.6/dist-packages/urllib3/connectionpool.py", line 306, in _raise_timeout
    raise ReadTimeoutError(self, url, "Read timed out. (read timeout=%s)" % timeout_value)
urllib3.exceptions.ReadTimeoutError: HTTPSConnectionPool(host='www.abuseipdb.com', port=443): Read timed out. (read timeout=15.0)

During handling of the above exception, another exception occurred:

Traceback (most recent call last):
  File "/var/misc-internet-applications/Multipurpose-Regex-Webscraper/py-cmd/regexscraper.py", line 55, in raw_scrape_pages
    page_text = requests.get(site, timeout=15.00).text
  File "/usr/local/lib/python3.6/dist-packages/requests/api.py", line 75, in get
    return request('get', url, params=params, **kwargs)
  File "/usr/local/lib/python3.6/dist-packages/requests/api.py", line 60, in request
    return session.request(method=method, url=url, **kwargs)
  File "/usr/local/lib/python3.6/dist-packages/requests/sessions.py", line 533, in request
    resp = self.send(prep, **send_kwargs)
  File "/usr/local/lib/python3.6/dist-packages/requests/sessions.py", line 646, in send
    r = adapter.send(request, **kwargs)
  File "/usr/local/lib/python3.6/dist-packages/requests/adapters.py", line 529, in send
    raise ReadTimeout(e, request=request)
requests.exceptions.ReadTimeout: HTTPSConnectionPool(host='www.abuseipdb.com', port=443): Read timed out. (read timeout=15.0)


Traceback (most recent call last):
  File "/usr/local/lib/python3.6/dist-packages/urllib3/connectionpool.py", line 384, in _make_request
    six.raise_from(e, None)
  File "<string>", line 2, in raise_from
  File "/usr/local/lib/python3.6/dist-packages/urllib3/connectionpool.py", line 380, in _make_request
    httplib_response = conn.getresponse()
  File "/usr/lib/python3.6/http/client.py", line 1346, in getresponse
    response.begin()
  File "/usr/lib/python3.6/http/client.py", line 307, in begin
    version, status, reason = self._read_status()
  File "/usr/lib/python3.6/http/client.py", line 268, in _read_status
    line = str(self.fp.readline(_MAXLINE + 1), "iso-8859-1")
  File "/usr/lib/python3.6/socket.py", line 586, in readinto
    return self._sock.recv_into(b)
  File "/usr/local/lib/python3.6/dist-packages/urllib3/contrib/pyopenssl.py", line 307, in recv_into
    raise timeout('The read operation timed out')
socket.timeout: The read operation timed out

During handling of the above exception, another exception occurred:

Traceback (most recent call last):
  File "/usr/local/lib/python3.6/dist-packages/requests/adapters.py", line 449, in send
    timeout=timeout
  File "/usr/local/lib/python3.6/dist-packages/urllib3/connectionpool.py", line 638, in urlopen
    _stacktrace=sys.exc_info()[2])
  File "/usr/local/lib/python3.6/dist-packages/urllib3/util/retry.py", line 367, in increment
    raise six.reraise(type(error), error, _stacktrace)
  File "/usr/local/lib/python3.6/dist-packages/urllib3/packages/six.py", line 686, in reraise
    raise value
  File "/usr/local/lib/python3.6/dist-packages/urllib3/connectionpool.py", line 600, in urlopen
    chunked=chunked)
  File "/usr/local/lib/python3.6/dist-packages/urllib3/connectionpool.py", line 386, in _make_request
    self._raise_timeout(err=e, url=url, timeout_value=read_timeout)
  File "/usr/local/lib/python3.6/dist-packages/urllib3/connectionpool.py", line 306, in _raise_timeout
    raise ReadTimeoutError(self, url, "Read timed out. (read timeout=%s)" % timeout_value)
urllib3.exceptions.ReadTimeoutError: HTTPSConnectionPool(host='www.abuseipdb.com', port=443): Read timed out. (read timeout=15.0)

During handling of the above exception, another exception occurred:

Traceback (most recent call last):
  File "/var/misc-internet-applications/Multipurpose-Regex-Webscraper/py-cmd/regexscraper.py", line 55, in raw_scrape_pages
    page_text = requests.get(site, timeout=15.00).text
  File "/usr/local/lib/python3.6/dist-packages/requests/api.py", line 75, in get
    return request('get', url, params=params, **kwargs)
  File "/usr/local/lib/python3.6/dist-packages/requests/api.py", line 60, in request
    return session.request(method=method, url=url, **kwargs)
  File "/usr/local/lib/python3.6/dist-packages/requests/sessions.py", line 533, in request
    resp = self.send(prep, **send_kwargs)
  File "/usr/local/lib/python3.6/dist-packages/requests/sessions.py", line 646, in send
    r = adapter.send(request, **kwargs)
  File "/usr/local/lib/python3.6/dist-packages/requests/adapters.py", line 529, in send
    raise ReadTimeout(e, request=request)
requests.exceptions.ReadTimeout: HTTPSConnectionPool(host='www.abuseipdb.com', port=443): Read timed out. (read timeout=15.0)


